============================= test session starts ==============================
platform linux -- Python 3.10.6, pytest-7.2.0, pluggy-1.0.0
rootdir: /root/projects/qvm
plugins: anyio-3.6.2
collected 47 items / 46 deselected / 1 selected

tst/qvm/integration/bench_test.py QVM::selection::costs::	1.0967254638671875e-05
FRP::online_compilation::costs::	2.841275691986084
F

=================================== FAILURES ===================================
_ TestBenchDiffBackendQvmFrpV2.test_independent_two_bench_frp[qasm-/root/projects/QASMBench/small//error_correctiond3_n5/error_correctiond3_n5.qasm,/root/projects/QASMBench/small//ipea_n2/ipea_n2.qasm-FakeBrooklyn-4-10] _

self = <bench_test.TestBenchDiffBackendQvmFrpV2 object at 0x7f5bb27aa590>
bench = 'qasm', nq = 10
qasm = '/root/projects/QASMBench/small//error_correctiond3_n5/error_correctiond3_n5.qasm,/root/projects/QASMBench/small//ipea_n2/ipea_n2.qasm'
backend = 'FakeBrooklyn', cu_size = 4

    def test_independent_two_bench_frp(self, bench, nq, qasm, backend, cu_size):
        """Execute qvm/frp exes on their own backend"""
        self.prepare_for_test(backend, cu_size)
>       super().test_two_bench_frp(bench, nq, qasm, independent=True)

tst/qvm/integration/bench_test.py:447: 
_ _ _ _ _ _ _ _ _ _ _ _ _ _ _ _ _ _ _ _ _ _ _ _ _ _ _ _ _ _ _ _ _ _ _ _ _ _ _ _ 
tst/qvm/integration/bench_test.py:386: in test_two_bench_frp
    fid_qvm = self.fid_calculator.calc_fidelity(
../qvm/util/circuit.py:274: in calc_fidelity
    fids = [
../qvm/util/circuit.py:275: in <listcomp>
    self._calc_single_fidelity(c, cnts, **kwargs)
../qvm/util/circuit.py:251: in _calc_single_fidelity
    pv_noise, _ = counts_to_vector(counts, num_qubits)
_ _ _ _ _ _ _ _ _ _ _ _ _ _ _ _ _ _ _ _ _ _ _ _ _ _ _ _ _ _ _ _ _ _ _ _ _ _ _ _ 

counts = {'1010': 4642, '1110': 14686, '0011': 743680, '0111': 17023, '1011': 39293, '0000': 8208, '0010': 32038, '1101': 44192, '1000': 3886, '0110': 6097, '0100': 33125, '1111': 25502, '0001': 27071, '1100': 15568, '1001': 6820, '0101': 26745}
num_qubits = 2

    def counts_to_vector(counts: Counts, num_qubits: int) -> Tuple[np.ndarray, int]:
        """Transforms Counts to a probability vector"""
        vec = np.zeros(2**num_qubits, dtype=float)
        shots = 0
        for key, val in counts.items():
            shots += val
>           vec[int(key, 2)] = val
E           IndexError: index 10 is out of bounds for axis 0 with size 4

/root/anaconda3/envs/qcs-noise/lib/python3.10/site-packages/qiskit/result/mitigation/utils.py:93: IndexError
------------------------------ Captured log call -------------------------------
WARNING  root:graph.py:571 Failed to grow a subgraph from root: 26, current visited status: {0, 1, 3, 4, 5, 6, 8, 10, 12, 13, 18, 19, 20, 21, 22, 23, 25, 26, 34, 35, 36, 37, 42, 43, 44, 45, 49, 50, 51, 54}, error message is 'Cannot grow a graph that satisfy the subgraph size from current root: 26'
WARNING  root:graph.py:571 Failed to grow a subgraph from root: 40, current visited status: {0, 1, 3, 4, 5, 6, 8, 10, 12, 13, 18, 19, 20, 21, 22, 25, 26, 34, 35, 36, 37, 40, 42, 43, 44, 45, 49, 50, 51, 54}, error message is 'Cannot grow a graph that satisfy the subgraph size from current root: 40'
WARNING  root:graph.py:571 Failed to grow a subgraph from root: 9, current visited status: {0, 1, 3, 4, 5, 6, 8, 9, 10, 12, 13, 18, 19, 20, 21, 22, 25, 26, 27, 28, 30, 31, 32, 34, 35, 36, 37, 38, 39, 40, 41, 42, 43, 44, 45, 49, 50, 51, 52, 54, 55, 56, 57}, error message is 'Cannot grow a graph that satisfy the subgraph size from current root: 9'
WARNING  root:graph.py:571 Failed to grow a subgraph from root: 7, current visited status: {0, 1, 3, 4, 5, 6, 7, 8, 9, 10, 12, 13, 14, 15, 18, 19, 20, 21, 22, 24, 25, 26, 27, 28, 29, 30, 31, 32, 34, 35, 36, 37, 38, 39, 40, 41, 42, 43, 44, 45, 46, 47, 48, 49, 50, 51, 52, 53, 54, 55, 56, 57, 58, 59, 60, 61}, error message is 'Cannot grow a graph that satisfy the subgraph size from current root: 7'
WARNING  root:graph.py:571 Failed to grow a subgraph from root: 62, current visited status: {0, 1, 3, 4, 5, 6, 7, 8, 9, 10, 12, 13, 14, 15, 18, 19, 20, 21, 22, 24, 25, 26, 27, 28, 29, 30, 31, 32, 34, 35, 36, 37, 38, 39, 40, 41, 42, 43, 44, 45, 46, 47, 48, 49, 50, 51, 52, 53, 54, 55, 56, 57, 58, 59, 60, 61, 62, 63, 64}, error message is 'Cannot grow a graph that satisfy the subgraph size from current root: 62'
WARNING  root:graph.py:571 Failed to grow a subgraph from root: 16, current visited status: {0, 1, 3, 4, 5, 6, 7, 8, 9, 10, 11, 12, 13, 14, 15, 16, 17, 18, 19, 20, 21, 22, 24, 25, 26, 27, 28, 29, 30, 31, 32, 34, 35, 36, 37, 38, 39, 40, 41, 42, 43, 44, 45, 46, 47, 48, 49, 50, 51, 52, 53, 54, 55, 56, 57, 58, 59, 60, 61, 62}, error message is 'Cannot grow a graph that satisfy the subgraph size from current root: 16'
WARNING  root:graph.py:571 Failed to grow a subgraph from root: 23, current visited status: {0, 1, 3, 4, 5, 6, 7, 8, 9, 10, 12, 13, 14, 15, 16, 18, 19, 20, 21, 22, 23, 24, 25, 26, 27, 28, 29, 30, 31, 32, 34, 35, 36, 37, 38, 39, 40, 41, 42, 43, 44, 45, 46, 47, 48, 49, 50, 51, 52, 53, 54, 55, 56, 57, 58, 59, 60, 61, 62}, error message is 'Cannot grow a graph that satisfy the subgraph size from current root: 23'
WARNING  root:graph.py:571 Failed to grow a subgraph from root: 17, current visited status: {0, 1, 3, 4, 5, 6, 7, 8, 9, 10, 11, 12, 13, 14, 15, 16, 17, 18, 19, 20, 21, 22, 23, 24, 25, 26, 27, 28, 29, 30, 31, 32, 34, 35, 36, 37, 38, 39, 40, 41, 42, 43, 44, 45, 46, 47, 48, 49, 50, 51, 52, 53, 54, 55, 56, 57, 58, 59, 60, 61, 62}, error message is 'Cannot grow a graph that satisfy the subgraph size from current root: 17'
WARNING  root:graph.py:571 Failed to grow a subgraph from root: 63, current visited status: {0, 1, 3, 4, 5, 6, 7, 8, 9, 10, 12, 13, 14, 15, 16, 17, 18, 19, 20, 21, 22, 23, 24, 25, 26, 27, 28, 29, 30, 31, 32, 34, 35, 36, 37, 38, 39, 40, 41, 42, 43, 44, 45, 46, 47, 48, 49, 50, 51, 52, 53, 54, 55, 56, 57, 58, 59, 60, 61, 62, 63, 64}, error message is 'Cannot grow a graph that satisfy the subgraph size from current root: 63'
WARNING  root:graph.py:571 Failed to grow a subgraph from root: 64, current visited status: {0, 1, 3, 4, 5, 6, 7, 8, 9, 10, 12, 13, 14, 15, 16, 17, 18, 19, 20, 21, 22, 23, 24, 25, 26, 27, 28, 29, 30, 31, 32, 34, 35, 36, 37, 38, 39, 40, 41, 42, 43, 44, 45, 46, 47, 48, 49, 50, 51, 52, 53, 54, 55, 56, 57, 58, 59, 60, 61, 62, 63, 64}, error message is 'Cannot grow a graph that satisfy the subgraph size from current root: 64'
WARNING  root:graph.py:571 Failed to grow a subgraph from root: 11, current visited status: {0, 1, 3, 4, 5, 6, 7, 8, 9, 10, 11, 12, 13, 14, 15, 16, 17, 18, 19, 20, 21, 22, 23, 24, 25, 26, 27, 28, 29, 30, 31, 32, 34, 35, 36, 37, 38, 39, 40, 41, 42, 43, 44, 45, 46, 47, 48, 49, 50, 51, 52, 53, 54, 55, 56, 57, 58, 59, 60, 61, 62, 63, 64}, error message is 'Cannot grow a graph that satisfy the subgraph size from current root: 11'
WARNING  root:graph.py:571 Failed to grow a subgraph from root: 33, current visited status: {0, 1, 3, 4, 5, 6, 7, 8, 9, 10, 11, 12, 13, 14, 15, 16, 17, 18, 19, 20, 21, 22, 23, 24, 25, 26, 27, 28, 29, 30, 31, 32, 33, 34, 35, 36, 37, 38, 39, 40, 41, 42, 43, 44, 45, 46, 47, 48, 49, 50, 51, 52, 53, 54, 55, 56, 57, 58, 59, 60, 61, 62, 63, 64}, error message is 'Cannot grow a graph that satisfy the subgraph size from current root: 33'
WARNING  root:graph.py:571 Failed to grow a subgraph from root: 2, current visited status: {0, 1, 2, 3, 4, 5, 6, 7, 8, 9, 10, 11, 12, 13, 14, 15, 16, 17, 18, 19, 20, 21, 22, 23, 24, 25, 26, 27, 28, 29, 30, 31, 32, 33, 34, 35, 36, 37, 38, 39, 40, 41, 42, 43, 44, 45, 46, 47, 48, 49, 50, 51, 52, 53, 54, 55, 56, 57, 58, 59, 60, 61, 62, 63, 64}, error message is 'Cannot grow a graph that satisfy the subgraph size from current root: 2'
WARNING  root:backend_manager.py:407 cannot compile on compute unit <qvm.model.compute_unit.ComputeUnit object at 0x7f5ba442fe80>, error: 'Number of qubits (5) in circuit-88 is greater than maximum (4) in the coupling_map'
WARNING  root:backend_manager.py:407 cannot compile on compute unit <qvm.model.compute_unit.ComputeUnit object at 0x7f5b4ea91a20>, error: 'Number of qubits (5) in circuit-88 is greater than maximum (4) in the coupling_map'
WARNING  root:backend_manager.py:407 cannot compile on compute unit <qvm.model.compute_unit.ComputeUnit object at 0x7f5b4c95bfd0>, error: 'Number of qubits (5) in circuit-88 is greater than maximum (4) in the coupling_map'
=============================== warnings summary ===============================
qcs/tst/qvm/integration/bench_test.py::TestBenchDiffBackendQvmFrpV2::test_independent_two_bench_frp[qasm-/root/projects/QASMBench/small//error_correctiond3_n5/error_correctiond3_n5.qasm,/root/projects/QASMBench/small//ipea_n2/ipea_n2.qasm-FakeBrooklyn-4-10]
qcs/tst/qvm/integration/bench_test.py::TestBenchDiffBackendQvmFrpV2::test_independent_two_bench_frp[qasm-/root/projects/QASMBench/small//error_correctiond3_n5/error_correctiond3_n5.qasm,/root/projects/QASMBench/small//ipea_n2/ipea_n2.qasm-FakeBrooklyn-4-10]
qcs/tst/qvm/integration/bench_test.py::TestBenchDiffBackendQvmFrpV2::test_independent_two_bench_frp[qasm-/root/projects/QASMBench/small//error_correctiond3_n5/error_correctiond3_n5.qasm,/root/projects/QASMBench/small//ipea_n2/ipea_n2.qasm-FakeBrooklyn-4-10]
qcs/tst/qvm/integration/bench_test.py::TestBenchDiffBackendQvmFrpV2::test_independent_two_bench_frp[qasm-/root/projects/QASMBench/small//error_correctiond3_n5/error_correctiond3_n5.qasm,/root/projects/QASMBench/small//ipea_n2/ipea_n2.qasm-FakeBrooklyn-4-10]
  /root/anaconda3/envs/qcs-noise/lib/python3.10/site-packages/qiskit/providers/fake_provider/fake_backend.py:462: PendingDeprecationWarning: "warnings" argument will be deprecated as part of the qiskit-aer 0.12.0 and subsequently removed
    noise_model = NoiseModel.from_backend(self, warnings=False)

-- Docs: https://docs.pytest.org/en/stable/how-to/capture-warnings.html
=========================== short test summary info ============================
FAILED tst/qvm/integration/bench_test.py::TestBenchDiffBackendQvmFrpV2::test_independent_two_bench_frp[qasm-/root/projects/QASMBench/small/error_correctiond3_n5/error_correctiond3_n5.qasm,/root/projects/QASMBench/small/ipea_n2/ipea_n2.qasm-FakeBrooklyn-4-10]
=========== 1 failed, 46 deselected, 4 warnings in 120.84s (0:02:00) ===========
