============================= test session starts ==============================
platform linux -- Python 3.10.6, pytest-7.2.0, pluggy-1.0.0
rootdir: /root/projects/qvm
plugins: anyio-3.6.2
collected 43 items / 42 deselected / 1 selected

tst/qvm/integration/bench_test.py QVM::selection::costs::	1.5735626220703125e-05
FRP::online_compilation::costs::	0.9616291522979736
F

=================================== FAILURES ===================================
_ TestBenchDiffBackendQvmFrpV2.test_independent_two_bench_frp[qasm-/root/projects/QASMBench/small//bb84_n8/bb84_n8.qasm,/root/projects/QASMBench/small//lpn_n5/lpn_n5.qasm-FakeCairo-4-10] _

self = <bench_test.TestBenchDiffBackendQvmFrpV2 object at 0x7f5d41959f00>
bench = 'qasm', nq = 10
qasm = '/root/projects/QASMBench/small//bb84_n8/bb84_n8.qasm,/root/projects/QASMBench/small//lpn_n5/lpn_n5.qasm'
backend = 'FakeCairo', cu_size = 4

    def test_independent_two_bench_frp(self, bench, nq, qasm, backend, cu_size):
        """Execute qvm/frp exes on their own backend"""
        self.prepare_for_test(backend, cu_size)
>       super().test_two_bench_frp(bench, nq, qasm, independent=True)

tst/qvm/integration/bench_test.py:446: 
_ _ _ _ _ _ _ _ _ _ _ _ _ _ _ _ _ _ _ _ _ _ _ _ _ _ _ _ _ _ _ _ _ _ _ _ _ _ _ _ 
tst/qvm/integration/bench_test.py:387: in test_two_bench_frp
    fid_qvm = self._fid_calculator.calc_fidelity(
../qvm/util/circuit.py:266: in calc_fidelity
    fids = [self._calc_single_fidelity(c, cnts, **kwargs) for c, cnts in zip(circ, counts)]
../qvm/util/circuit.py:266: in <listcomp>
    fids = [self._calc_single_fidelity(c, cnts, **kwargs) for c, cnts in zip(circ, counts)]
../qvm/util/circuit.py:246: in _calc_single_fidelity
    pv_noise, _ = counts_to_vector(counts, num_qubits)
_ _ _ _ _ _ _ _ _ _ _ _ _ _ _ _ _ _ _ _ _ _ _ _ _ _ _ _ _ _ _ _ _ _ _ _ _ _ _ _ 

counts = {'0 1 1 1 1 1 1 0': 1, '0 1 0 0 1 0 1 1': 1, '0 0 0 0 1 0 1 0': 2, '0 0 0 1 1 1 1 0': 1, '1 1 0 0 1 0 1 1': 1, '0 1 0 ... '1 1 1 0 1 1 0 1': 47, '1 1 1 0 0 1 0 1': 3267, '0 0 1 1 1 0 0 1': 378, '0 1 1 1 0 0 1 0': 114, '1 0 1 0 0 0 1 0': 15}
num_qubits = 8

    def counts_to_vector(counts: Counts, num_qubits: int) -> Tuple[np.ndarray, int]:
        """Transforms Counts to a probability vector"""
        vec = np.zeros(2**num_qubits, dtype=float)
        shots = 0
        for key, val in counts.items():
            shots += val
>           vec[int(key, 2)] = val
E           ValueError: invalid literal for int() with base 2: '0 1 1 1 1 1 1 0'

/root/anaconda3/envs/qcs-noise/lib/python3.10/site-packages/qiskit/result/mitigation/utils.py:93: ValueError
------------------------------ Captured log call -------------------------------
WARNING  root:graph.py:571 Failed to grow a subgraph from root: 9, current visited status: {2, 3, 5, 8, 9, 11, 14, 16, 19}, error message is 'Cannot grow a graph that satisfy the subgraph size from current root: 9'
WARNING  root:graph.py:571 Failed to grow a subgraph from root: 20, current visited status: {2, 3, 5, 8, 9, 11, 14, 16, 18, 19, 20, 21, 23, 24}, error message is 'Cannot grow a graph that satisfy the subgraph size from current root: 20'
WARNING  root:graph.py:571 Failed to grow a subgraph from root: 17, current visited status: {2, 3, 5, 8, 9, 10, 11, 12, 13, 14, 15, 16, 17, 18, 19, 20, 21, 23, 24}, error message is 'Cannot grow a graph that satisfy the subgraph size from current root: 17'
WARNING  root:graph.py:571 Failed to grow a subgraph from root: 6, current visited status: {0, 1, 2, 3, 4, 5, 6, 7, 8, 9, 10, 11, 12, 13, 14, 15, 16, 17, 18, 19, 20, 21, 23, 24}, error message is 'Cannot grow a graph that satisfy the subgraph size from current root: 6'
WARNING  root:graph.py:571 Failed to grow a subgraph from root: 22, current visited status: {0, 1, 2, 3, 4, 5, 6, 7, 8, 9, 10, 11, 12, 13, 14, 15, 16, 17, 18, 19, 20, 21, 22, 23, 24, 25, 26}, error message is 'Cannot grow a graph that satisfy the subgraph size from current root: 22'
WARNING  root:graph.py:571 Failed to grow a subgraph from root: 25, current visited status: {0, 1, 2, 3, 4, 5, 6, 7, 8, 9, 10, 11, 12, 13, 14, 15, 16, 17, 18, 19, 20, 21, 22, 23, 24, 25, 26}, error message is 'Cannot grow a graph that satisfy the subgraph size from current root: 25'
WARNING  root:graph.py:571 Failed to grow a subgraph from root: 26, current visited status: {0, 1, 2, 3, 4, 5, 6, 7, 8, 9, 10, 11, 12, 13, 14, 15, 16, 17, 18, 19, 20, 21, 22, 23, 24, 25, 26}, error message is 'Cannot grow a graph that satisfy the subgraph size from current root: 26'
WARNING  root:backend_manager.py:407 cannot compile on compute unit <qvm.model.compute_unit.ComputeUnit object at 0x7f5d3c317fa0>, error: 'Number of qubits (8) in circuit-88 is greater than maximum (4) in the coupling_map'
WARNING  root:backend_manager.py:407 cannot compile on compute unit <qvm.model.compute_unit.ComputeUnit object at 0x7f5d3495c580>, error: 'Number of qubits (5) in circuit-90 is greater than maximum (4) in the coupling_map'
=============================== warnings summary ===============================
qcs/tst/qvm/integration/bench_test.py::TestBenchDiffBackendQvmFrpV2::test_independent_two_bench_frp[qasm-/root/projects/QASMBench/small//bb84_n8/bb84_n8.qasm,/root/projects/QASMBench/small//lpn_n5/lpn_n5.qasm-FakeCairo-4-10]
qcs/tst/qvm/integration/bench_test.py::TestBenchDiffBackendQvmFrpV2::test_independent_two_bench_frp[qasm-/root/projects/QASMBench/small//bb84_n8/bb84_n8.qasm,/root/projects/QASMBench/small//lpn_n5/lpn_n5.qasm-FakeCairo-4-10]
qcs/tst/qvm/integration/bench_test.py::TestBenchDiffBackendQvmFrpV2::test_independent_two_bench_frp[qasm-/root/projects/QASMBench/small//bb84_n8/bb84_n8.qasm,/root/projects/QASMBench/small//lpn_n5/lpn_n5.qasm-FakeCairo-4-10]
qcs/tst/qvm/integration/bench_test.py::TestBenchDiffBackendQvmFrpV2::test_independent_two_bench_frp[qasm-/root/projects/QASMBench/small//bb84_n8/bb84_n8.qasm,/root/projects/QASMBench/small//lpn_n5/lpn_n5.qasm-FakeCairo-4-10]
  /root/anaconda3/envs/qcs-noise/lib/python3.10/site-packages/qiskit/providers/fake_provider/fake_backend.py:462: PendingDeprecationWarning: "warnings" argument will be deprecated as part of the qiskit-aer 0.12.0 and subsequently removed
    noise_model = NoiseModel.from_backend(self, warnings=False)

qcs/tst/qvm/integration/bench_test.py::TestBenchDiffBackendQvmFrpV2::test_independent_two_bench_frp[qasm-/root/projects/QASMBench/small//bb84_n8/bb84_n8.qasm,/root/projects/QASMBench/small//lpn_n5/lpn_n5.qasm-FakeCairo-4-10]
qcs/tst/qvm/integration/bench_test.py::TestBenchDiffBackendQvmFrpV2::test_independent_two_bench_frp[qasm-/root/projects/QASMBench/small//bb84_n8/bb84_n8.qasm,/root/projects/QASMBench/small//lpn_n5/lpn_n5.qasm-FakeCairo-4-10]
qcs/tst/qvm/integration/bench_test.py::TestBenchDiffBackendQvmFrpV2::test_independent_two_bench_frp[qasm-/root/projects/QASMBench/small//bb84_n8/bb84_n8.qasm,/root/projects/QASMBench/small//lpn_n5/lpn_n5.qasm-FakeCairo-4-10]
qcs/tst/qvm/integration/bench_test.py::TestBenchDiffBackendQvmFrpV2::test_independent_two_bench_frp[qasm-/root/projects/QASMBench/small//bb84_n8/bb84_n8.qasm,/root/projects/QASMBench/small//lpn_n5/lpn_n5.qasm-FakeCairo-4-10]
qcs/tst/qvm/integration/bench_test.py::TestBenchDiffBackendQvmFrpV2::test_independent_two_bench_frp[qasm-/root/projects/QASMBench/small//bb84_n8/bb84_n8.qasm,/root/projects/QASMBench/small//lpn_n5/lpn_n5.qasm-FakeCairo-4-10]
qcs/tst/qvm/integration/bench_test.py::TestBenchDiffBackendQvmFrpV2::test_independent_two_bench_frp[qasm-/root/projects/QASMBench/small//bb84_n8/bb84_n8.qasm,/root/projects/QASMBench/small//lpn_n5/lpn_n5.qasm-FakeCairo-4-10]
  /root/anaconda3/envs/qcs-noise/lib/python3.10/site-packages/qiskit_aer/noise/device/models.py:365: UserWarning: Device model returned an invalid T_2 relaxation time greater than the theoretical maximum value 2 * T_1 (196328.6961892367 > 2 * 96478.49546055387). Truncating to maximum value.
    warn("Device model returned an invalid T_2 relaxation time greater than"

qcs/tst/qvm/integration/bench_test.py::TestBenchDiffBackendQvmFrpV2::test_independent_two_bench_frp[qasm-/root/projects/QASMBench/small//bb84_n8/bb84_n8.qasm,/root/projects/QASMBench/small//lpn_n5/lpn_n5.qasm-FakeCairo-4-10]
  /root/anaconda3/envs/qcs-noise/lib/python3.10/site-packages/qiskit_aer/noise/device/models.py:365: UserWarning: Device model returned an invalid T_2 relaxation time greater than the theoretical maximum value 2 * T_1 (0.00019632869618923672 > 2 * 9.647849546055387e-05). Truncating to maximum value.
    warn("Device model returned an invalid T_2 relaxation time greater than"

-- Docs: https://docs.pytest.org/en/stable/how-to/capture-warnings.html
=========================== short test summary info ============================
FAILED tst/qvm/integration/bench_test.py::TestBenchDiffBackendQvmFrpV2::test_independent_two_bench_frp[qasm-/root/projects/QASMBench/small/bb84_n8/bb84_n8.qasm,/root/projects/QASMBench/small/lpn_n5/lpn_n5.qasm-FakeCairo-4-10]
================ 1 failed, 42 deselected, 11 warnings in 31.00s ================
